Workbook

Sheet Daily Data Entry
B3: PPE Burn Rate Calculator Data Entry
E4: Day 1 | F4: Day 2 | G4: Day 3 | H4: Day 4 | I4: Day 5 | J4: Day 6 | K4: Day 7 | L4: Day 8 | M4: Day 9 | N4: Day 10 | O4: Day 11 | P4: Day 12 | Q4: Day 13 | R4: Day 14
E5: XX/XX/2021 | F5: XX/XX/2021 | G5: XX/XX/2021 | H5: XX/XX/2021 | I5: XX/XX/2021 | J5: XX/XX/2021 | K5: XX/XX/2021 | L5: XX/XX/2021 | M5: XX/XX/2021 | N5: XX/XX/2021 | O5: XX/XX/2021 | P5: XX/XX/2021 | Q5: XX/XX/2021 | R5: XX/XX/2021
E6: How Many COVID-19 Residents are Being Treated at Start of the Day? Enter Below.
B7: Number of Suspected and Confirmed COVID-19 Residents
B8: Type of PPE | D8: Quantity in Box | E8: How Many Full Boxes Are Available/Remaining at Start of the Day? Enter Below. (ie.1 box of 100 gowns, 1 box/package of 1 face shields, etc.)
B9: Washable Gowns | D9: 0
B10: Gloves | C10: small | D10: 0
C11: medium | D11: 0
C12: large | D12: 0
C13: extra large | D13: 0
B14: N95 Masks | D14: 0
B15: Surgical Masks | D15: 0
B16: Respirators | D16: 0
B17: Face Shields | D17: 0
B18: Eye Protection - Goggles | D18: 0
B19: Disposable Gowns | D19: 0
B20: Fluid Resistant Gowns
B21: Other
B22: Other
B23: Other
B25: This spreadsheet is designed to help you track how quickly PPE is being used at your facility.
B27: 1) To start, go to the "Daily Data Entry" sheet and enter dates below Day 1, Day 2, Day 3, etc.
B28: 2) Enter the total number of suspected and confirmed COVID-19 patients at the start of each day in the "Suspected and Confirmed COVID-19 Patients" row.
B29: 3) At the start of each day, determine how many full boxes of PPE are remaining from the day before. Do this for each type of PPE and enter them into the appropriate box.
B30: 4) "Type of PPE" refers to the PPE components you have in stock. "Gowns," "gloves," "respirators," "surgical masks," and "face shields" have been filled in for you. Note: Additional types or brands of PPE can be added in the "Other" Type of PPE section as well.
B31: 5) Make sure that each box of PPE has the same number of individual units (Example: a box of gloves may have 200 individual gloves). If they do not, start a new "Type of PPE" category in the cells that says "Other".
B32: 6) Enter the number of full boxes of each Type of PPE starting at Day 1 into the yellow cells. Note: You do not need data for all 14 days, but at least 2 consecutive days of data are needed to calculate a consumption rate (Burn Rate).
B37: Total Number of PPE Used per Day (negative numbers indicate daily supply increase) | T37: Average Consumption of PPE used per Day
B39: Type of PPE | D39: Day 1 -Day 2 | E39: Day 2 - Day 3 | F39: Day 3 - Day 4 | G39: Day 4 - Day 5 | H39: Day 5 - Day 6 | I39: Day 6 - Day 7 | J39: Day 7 - Day 8 | K39: Day 8 - Day 9 | L39: Day 9 - Day 10 | M39: Day 10 - Day 11 | N39: Day 11 - Day 12 | O39: Day 12 - Day 13 | P39: Day 13 - Day 14 | T39: Type of PPE | V39: Burn Rate
B40: =B9 -> Washable Gowns | D40: =IF(F9="","", (D9*E9-(D9*F9))) | E40: =IF(G9="","", ((D9*F9)-(D9*G9))) | F40: =IF(H9="","", (D9*G9-(D9*H9))) | G40: =IF(I9="","", (D9*H9-(D9*I9))) | H40: =IF(J9="","", (D9*I9-(D9*J9))) | I40: =IF(K9="","", (D9*J9-(D9*K9))) | J40: =IF(L9="","", (D9*K9-(D9*L9))) | K40: =IF(M9="","", (D9*L9-(D9*M9))) | L40: =IF(N9="","", (D9*M9-(D9*N9))) | M40: =IF(O9="","", (D9*N9-(D9*O9))) | N40: =IF(P9="","", (D9*O9-(D9*P9))) | O40: =IF(Q9="","", (D9*P9-(D9*Q9))) | P40: =IF(R9="","", (D9*Q9-(D9*R9))) | T40: ='Calculator Summary'!B5 -> Washable Gowns | V40: =IF(SUM(D40:P40)>0,AVERAGE(D40:P40),"")
B41: Gloves (pairs) | C41: =IF(C10="","",C10) -> small | D41: =IF(F10="","",((D10*E10)/2)-((D10*F10)/2)) | E41: =IF(G10="","",((D10*F10)/2)-((D10*G10)/2)) | F41: =IF(H10="","",((D10*G10)/2)-((D10*H10)/2)) | G41: =IF(I10="","",((D10*H10)/2)-((D10*I10)/2)) | H41: =IF(J10="","",((D10*I10)/2)-((D10*J10)/2)) | I41: =IF(K10="","",((D10*J10)/2)-((D10*K10)/2)) | J41: =IF(L10="","",((D10*K10)/2)-((D10*L10)/2)) | K41: =IF(M10="","",((D10*L10)/2)-((D10*M10)/2)) | L41: =IF(N10="","",((D10*M10)/2)-((D10*N10)/2)) | M41: =IF(O10="","",((D10*N10)/2)-((D10*O10)/2)) | N41: =IF(P10="","",((D10*O10)/2)-((D10*P10)/2)) | O41: =IF(Q10="","",((D10*P10)/2)-((D10*Q10)/2)) | P41: =IF(R10="","",((D10*Q10)/2)-((D10*R10)/2)) | T41: Gloves (pairs) | U41: ='Calculator Summary'!C6 -> small | V41: =IF(SUM(D41:P41)>0,AVERAGE(D41:P41),"")
C42: =IF(C11="","",C11) -> medium | D42: =IF(F11="","",((D11*E11)/2)-((D11*F11)/2)) | E42: =IF(G11="","",((D11*F11)/2)-((D11*G11)/2)) | F42: =IF(H11="","",((D11*G11)/2)-((D11*H11)/2)) | G42: =IF(I11="","",((D11*H11)/2)-((D11*I11)/2)) | H42: =IF(J11="","",((D11*I11)/2)-((D11*J11)/2)) | I42: =IF(K11="","",((D11*J11)/2)-((D11*K11)/2)) | J42: =IF(L11="","",((D11*K11)/2)-((D11*L11)/2)) | K42: =IF(M11="","",((D11*L11)/2)-((D11*M11)/2)) | L42: =IF(N11="","",((D11*M11)/2)-((D11*N11)/2)) | M42: =IF(O11="","",((D11*N11)/2)-((D11*O11)/2)) | N42: =IF(P11="","",((D11*O11)/2)-((D11*P11)/2)) | O42: =IF(Q11="","",((D11*P11)/2)-((D11*Q11)/2)) | P42: =IF(R11="","",((D11*Q11)/2)-((D11*R11)/2)) | U42: ='Calculator Summary'!C7 -> medium | V42: =IF(SUM(D42:P42)>0,AVERAGE(D42:P42),"")
C43: =IF(C12="","",C12) -> large | D43: =IF(F12="","",((D12*E12)/2)-((D12*F12)/2)) | E43: =IF(G12="","",((D12*F12)/2)-((D12*G12)/2)) | F43: =IF(H12="","",((D12*G12)/2)-((D12*H12)/2)) | G43: =IF(I12="","",((D12*H12)/2)-((D12*I12)/2)) | H43: =IF(J12="","",((D12*I12)/2)-((D12*J12)/2)) | I43: =IF(K12="","",((D12*J12)/2)-((D12*K12)/2)) | J43: =IF(L12="","",((D12*K12)/2)-((D12*L12)/2)) | K43: =IF(M12="","",((D12*L12)/2)-((D12*M12)/2)) | L43: =IF(N12="","",((D12*M12)/2)-((D12*N12)/2)) | M43: =IF(O12="","",((D12*N12)/2)-((D12*O12)/2)) | N43: =IF(P12="","",((D12*O12)/2)-((D12*P12)/2)) | O43: =IF(Q12="","",((D12*P12)/2)-((D12*Q12)/2)) | P43: =IF(R12="","",((D12*Q12)/2)-((D12*R12)/2)) | U43: ='Calculator Summary'!C8 -> large | V43: =IF(SUM(D43:P43)>0,AVERAGE(D43:P43),"")
C44: =IF(C13="","",C13) -> extra large | D44: =IF(F13="","",((D13*E13)/2)-((D13*F13)/2)) | E44: =IF(G13="","",((D13*F13)/2)-((D13*G13)/2)) | F44: =IF(H13="","",((D13*G13)/2)-((D13*H13)/2)) | G44: =IF(I13="","",((D13*H13)/2)-((D13*I13)/2)) | H44: =IF(J13="","",((D13*I13)/2)-((D13*J13)/2)) | I44: =IF(K13="","",((D13*J13)/2)-((D13*K13)/2)) | J44: =IF(L13="","",((D13*K13)/2)-((D13*L13)/2)) | K44: =IF(M13="","",((D13*L13)/2)-((D13*M13)/2)) | L44: =IF(N13="","",((D13*M13)/2)-((D13*N13)/2)) | M44: =IF(O13="","",((D13*N13)/2)-((D13*O13)/2)) | N44: =IF(P13="","",((D13*O13)/2)-((D13*P13)/2)) | O44: =IF(Q13="","",((D13*P13)/2)-((D13*Q13)/2)) | P44: =IF(R13="","",((D13*Q13)/2)-((D13*R13)/2)) | U44: ='Calculator Summary'!C9 -> extra large | V44: =IF(SUM(D44:P44)>0,AVERAGE(D44:P44),"")
B45: =B14 -> N95 Masks | D45: =IF(F14="","", (D14*E14-(D14*F14))) | E45: =IF(G14="","", (D14*F14-(D14*G14))) | F45: =IF(H14="","", (D14*G14-(D14*H14))) | G45: =IF(I14="","", (D14*H14-(D14*I14))) | H45: =IF(J14="","", (D14*I14-(D14*J14))) | I45: =IF(K14="","", (D14*J14-(D14*K14))) | J45: =IF(L14="","", (D14*K14-(D14*L14))) | K45: =IF(M14="","", (D14*L14-(D14*M14))) | L45: =IF(N14="","", (D14*M14-(D14*N14))) | M45: =IF(O14="","", (D14*N14-(D14*O14))) | N45: =IF(P14="","", (D14*O14-(D14*P14))) | O45: =IF(Q14="","", (D14*P14-(D14*Q14))) | P45: =IF(R14="","", (D14*Q14-(D14*R14))) | T45: ='Calculator Summary'!B10 -> N95 Masks | V45: =IF(SUM(D45:P45)>0,AVERAGE(D45:P45),"")
B46: =B15 -> Surgical Masks | D46: =IF(F15="","", (D15*E15-(D15*F15))) | E46: =IF(G15="","", (D15*F15-(D15*G15))) | F46: =IF(H15="","", (D15*G15-(D15*H15))) | G46: =IF(I15="","", (D15*H15-(D15*I15))) | H46: =IF(J15="","", (D15*I15-(D15*J15))) | I46: =IF(K15="","", (D15*J15-(D15*K15))) | J46: =IF(L15="","", (D15*K15-(D15*L15))) | K46: =IF(M15="","", (D15*L15-(D15*M15))) | L46: =IF(N15="","", (D15*M15-(D15*N15))) | M46: =IF(O15="","", (D15*N15-(D15*O15))) | N46: =IF(P15="","", (D15*O15-(D15*P15))) | O46: =IF(Q15="","", (D15*P15-(D15*Q15))) | P46: =IF(R15="","", (D15*Q15-(D15*R15))) | T46: ='Calculator Summary'!B11 -> Surgical Masks | V46: =IF(SUM(D46:P46)>0,AVERAGE(D46:P46),"")
B47: =B16 -> Respirators | D47: =IF(F16="","", (D16*E16-(D16*F16))) | E47: =IF(G16="","", (D16*F16-(D16*G16))) | F47: =IF(H16="","", (D16*G16-(D16*H16))) | G47: =IF(I16="","", (D16*H16-(D16*I16))) | H47: =IF(J16="","", (D16*I16-(D16*J16))) | I47: =IF(K16="","", (D16*J16-(D16*K16))) | J47: =IF(L16="","", (D16*K16-(D16*L16))) | K47: =IF(M16="","", (D16*L16-(D16*M16))) | L47: =IF(N16="","", (D16*M16-(D16*N16))) | M47: =IF(O16="","", (D16*N16-(D16*O16))) | N47: =IF(P16="","", (D16*O16-(D16*P16))) | O47: =IF(Q16="","", (D16*P16-(D16*Q16))) | P47: =IF(R16="","", (D16*Q16-(D16*R16))) | T47: ='Calculator Summary'!B12 -> Respirators | V47: =IF(SUM(D47:P47)>0,AVERAGE(D47:P47),"")
B48: =B17 -> Face Shields | D48: =IF(F17="","", (D17*E17-(D17*F17))) | E48: =IF(G17="","", (D17*F17-(D17*G17))) | F48: =IF(H17="","", (D17*G17-(D17*H17))) | G48: =IF(I17="","", (D17*H17-(D17*I17))) | H48: =IF(J17="","", (D17*I17-(D17*J17))) | I48: =IF(K17="","", (D17*J17-(D17*K17))) | J48: =IF(L17="","", (D17*K17-(D17*L17))) | K48: =IF(M17="","", (D17*L17-(D17*M17))) | L48: =IF(N17="","", (D17*M17-(D17*N17))) | M48: =IF(O17="","", (D17*N17-(D17*O17))) | N48: =IF(P17="","", (D17*O17-(D17*P17))) | O48: =IF(Q17="","", (D17*P17-(D17*Q17))) | P48: =IF(R17="","", (D17*Q17-(D17*R17))) | T48: ='Calculator Summary'!B13 -> Face Shields | V48: =IF(SUM(D48:P48)>0,AVERAGE(D48:P48),"")
B49: =IF(B18="","",B18) -> Eye Protection - Goggles | D49: =IF(F18="","", (D18*E18-(D18*F18))) | E49: =IF(G18="","", (D18*F18-(D18*G18))) | F49: =IF(H18="","", (D18*G18-(D18*H18))) | G49: =IF(I18="","", (D18*H18-(D18*I18))) | H49: =IF(J18="","", (D18*I18-(D18*J18))) | I49: =IF(K18="","", (D18*J18-(D18*K18))) | J49: =IF(L18="","", (D18*K18-(D18*L18))) | K49: =IF(M18="","", (D18*L18-(D18*M18))) | L49: =IF(N18="","", (D18*M18-(D18*N18))) | M49: =IF(O18="","", (D18*N18-(D18*O18))) | N49: =IF(P18="","", (D18*O18-(D18*P18))) | O49: =IF(Q18="","", (D18*P18-(D18*Q18))) | P49: =IF(R18="","", (D18*Q18-(D18*R18))) | T49: ='Calculator Summary'!B14 -> Eye Protection - Goggles | V49: =IF(SUM(D49:P49)>0,AVERAGE(D49:P49),"")
...

Sheet Calculator Summary
B3: Total Number of PPE Used per Day (negative numbers indicate daily supply increase) | S3: Average Consumption of PPE used per Day
B4: Type of PPE | D4: Day 1 -Day 2 | E4: Day 2 - Day 3 | F4: Day 3 - Day 4 | G4: Day 4 - Day 5 | H4: Day 5 - Day 6 | I4: Day 6 - Day 7 | J4: Day 7 - Day 8 | K4: Day 8 - Day 9 | L4: Day 9 - Day 10 | M4: Day 10 - Day 11 | N4: Day 11 - Day 12 | O4: Day 12 - Day 13 | P4: Day 13 - Day 14 | S4: Type of PPE | U4: Burn Rate
B5: ='Daily Data Entry'!B40:C40 -> Washable Gowns | D5: ='Daily Data Entry'!D40 | E5: ='Daily Data Entry'!E40 | F5: ='Daily Data Entry'!F40 | G5: ='Daily Data Entry'!G40 | H5: ='Daily Data Entry'!H40 | I5: ='Daily Data Entry'!I40 | J5: ='Daily Data Entry'!J40 | K5: ='Daily Data Entry'!K40 | ... P5: ='Daily Data Entry'!P40 | S5: =B5 -> Washable Gowns | U5: ='Daily Data Entry'!V40
B6: Gloves (pairs) | C6: ='Daily Data Entry'!C10 -> small | D6: ='Daily Data Entry'!D41 | E6: ='Daily Data Entry'!E41 | F6: ='Daily Data Entry'!F41 | G6: ='Daily Data Entry'!G41 | H6: ='Daily Data Entry'!H41 | I6: ='Daily Data Entry'!I41 | J6: ='Daily Data Entry'!J41 | K6: ='Daily Data Entry'!K41 | ... P6: ='Daily Data Entry'!P41 | S6: Gloves (pairs) | T6: =C6 -> small | U6: ='Daily Data Entry'!V41
C7: ='Daily Data Entry'!C11 -> medium | D7: ='Daily Data Entry'!D42 | E7: ='Daily Data Entry'!E42 | F7: ='Daily Data Entry'!F42 | G7: ='Daily Data Entry'!G42 | H7: ='Daily Data Entry'!H42 | I7: ='Daily Data Entry'!I42 | J7: ='Daily Data Entry'!J42 | K7: ='Daily Data Entry'!K42 | ... P7: ='Daily Data Entry'!P42 | T7: =C7 -> medium | U7: ='Daily Data Entry'!V42
C8: ='Daily Data Entry'!C12 -> large | D8: ='Daily Data Entry'!D43 | E8: ='Daily Data Entry'!E43 | F8: ='Daily Data Entry'!F43 | G8: ='Daily Data Entry'!G43 | H8: ='Daily Data Entry'!H43 | I8: ='Daily Data Entry'!I43 | J8: ='Daily Data Entry'!J43 | K8: ='Daily Data Entry'!K43 | ... P8: ='Daily Data Entry'!P43 | T8: =C8 -> large | U8: ='Daily Data Entry'!V43
C9: ='Daily Data Entry'!C13 -> extra large | D9: ='Daily Data Entry'!D44 | E9: ='Daily Data Entry'!E44 | F9: ='Daily Data Entry'!F44 | G9: ='Daily Data Entry'!G44 | H9: ='Daily Data Entry'!H44 | I9: ='Daily Data Entry'!I44 | J9: ='Daily Data Entry'!J44 | K9: ='Daily Data Entry'!K44 | ... P9: ='Daily Data Entry'!P44 | T9: =C9 -> extra large | U9: ='Daily Data Entry'!V44
B10: ='Daily Data Entry'!B14:C14 -> N95 Masks | D10: ='Daily Data Entry'!D45 | E10: ='Daily Data Entry'!E45 | F10: ='Daily Data Entry'!F45 | G10: ='Daily Data Entry'!G45 | H10: ='Daily Data Entry'!H45 | I10: ='Daily Data Entry'!I45 | J10: ='Daily Data Entry'!J45 | K10: ='Daily Data Entry'!K45 | ... P10: ='Daily Data Entry'!P45 | S10: =B10 -> N95 Masks | U10: ='Daily Data Entry'!V45
B11: ='Daily Data Entry'!B15:C15 -> Surgical Masks | D11: ='Daily Data Entry'!D46 | E11: ='Daily Data Entry'!E46 | F11: ='Daily Data Entry'!F46 | G11: ='Daily Data Entry'!G46 | H11: ='Daily Data Entry'!H46 | I11: ='Daily Data Entry'!I46 | J11: ='Daily Data Entry'!J46 | K11: ='Daily Data Entry'!K46 | ... P11: ='Daily Data Entry'!P46 | S11: =B11 -> Surgical Masks | U11: ='Daily Data Entry'!V46
B12: ='Daily Data Entry'!B66:C66 -> Respirators | D12: ='Daily Data Entry'!D47 | E12: ='Daily Data Entry'!E47 | F12: ='Daily Data Entry'!F47 | G12: ='Daily Data Entry'!G47 | H12: ='Daily Data Entry'!H47 | I12: ='Daily Data Entry'!I47 | J12: ='Daily Data Entry'!J47 | K12: ='Daily Data Entry'!K47 | ... P12: ='Daily Data Entry'!P47 | S12: =B12 -> Respirators | U12: ='Daily Data Entry'!V47
B13: ='Daily Data Entry'!B17:C17 -> Face Shields | D13: ='Daily Data Entry'!D48 | E13: ='Daily Data Entry'!E48 | F13: ='Daily Data Entry'!F48 | G13: ='Daily Data Entry'!G48 | H13: ='Daily Data Entry'!H48 | I13: ='Daily Data Entry'!I48 | J13: ='Daily Data Entry'!J48 | K13: ='Daily Data Entry'!K48 | ... P13: ='Daily Data Entry'!P48 | S13: =B13 -> Face Shields | U13: ='Daily Data Entry'!V48
B14: ='Daily Data Entry'!B18:C18 -> Eye Protection - Goggles | D14: ='Daily Data Entry'!D49 | E14: ='Daily Data Entry'!E49 | F14: ='Daily Data Entry'!F49 | G14: ='Daily Data Entry'!G49 | H14: ='Daily Data Entry'!H49 | I14: ='Daily Data Entry'!I49 | J14: ='Daily Data Entry'!J49 | K14: ='Daily Data Entry'!K49 | ... P14: ='Daily Data Entry'!P49 | S14: =B14 -> Eye Protection - Goggles | U14: ='Daily Data Entry'!V49
B15: ='Daily Data Entry'!B19:C19 -> Disposable Gowns | D15: ='Daily Data Entry'!D50 | E15: ='Daily Data Entry'!E50 | F15: ='Daily Data Entry'!F50 | G15: ='Daily Data Entry'!G50 | H15: ='Daily Data Entry'!H50 | I15: ='Daily Data Entry'!I50 | J15: ='Daily Data Entry'!J50 | K15: ='Daily Data Entry'!K50 | ... P15: ='Daily Data Entry'!P50 | S15: =B15 -> Disposable Gowns | U15: ='Daily Data Entry'!V50
B16: ='Daily Data Entry'!B20:C20 -> Fluid Resistant Gowns | D16: ='Daily Data Entry'!D51 | E16: ='Daily Data Entry'!E51 | F16: ='Daily Data Entry'!F51 | G16: ='Daily Data Entry'!G51 | H16: ='Daily Data Entry'!H51 | I16: ='Daily Data Entry'!I51 | J16: ='Daily Data Entry'!J51 | K16: ='Daily Data Entry'!K51 | ... P16: ='Daily Data Entry'!P51 | S16: =B16 -> Fluid Resistant Gowns | U16: ='Daily Data Entry'!V51
B17: ='Daily Data Entry'!B21:C21 -> Other | D17: ='Daily Data Entry'!D52 | E17: ='Daily Data Entry'!E52 | F17: ='Daily Data Entry'!F52 | G17: ='Daily Data Entry'!G52 | H17: ='Daily Data Entry'!H52 | I17: ='Daily Data Entry'!I52 | J17: ='Daily Data Entry'!J52 | K17: ='Daily Data Entry'!K52 | ... P17: ='Daily Data Entry'!P52 | S17: =B17 -> Other | U17: ='Daily Data Entry'!V52
B18: ='Daily Data Entry'!B22:C22 -> Other | D18: ='Daily Data Entry'!D53 | E18: ='Daily Data Entry'!E53 | F18: ='Daily Data Entry'!F53 | G18: ='Daily Data Entry'!G53 | H18: ='Daily Data Entry'!H53 | I18: ='Daily Data Entry'!I53 | J18: ='Daily Data Entry'!J53 | K18: ='Daily Data Entry'!K53 | ... P18: ='Daily Data Entry'!P53 | S18: =B18 -> Other | U18: ='Daily Data Entry'!V53
B19: ='Daily Data Entry'!B23:C23 -> Other | D19: ='Daily Data Entry'!D54 | E19: ='Daily Data Entry'!E54 | F19: ='Daily Data Entry'!F54 | G19: ='Daily Data Entry'!G54 | H19: ='Daily Data Entry'!H54 | I19: ='Daily Data Entry'!I54 | J19: ='Daily Data Entry'!J54 | K19: ='Daily Data Entry'!K54 | ... P19: ='Daily Data Entry'!P54 | S19: =B19 -> Other | U19: ='Daily Data Entry'!V54
B21: Number of Days Supply Remaining | S21: Average Consumption of PPE used per Patient, per Day
B22: Type of PPE | D22: Day 1 | E22: Day 2 | F22: Day 3 | G22: Day 4 | H22: Day 5 | I22: Day 6 | J22: Day 7 | K22: Day 8 | L22: Day 9 | M22: Day 10 | N22: Day 11 | O22: Day 12 | P22: Day 13 | Q22: Day 14 | S22: Type of PPE | U22: Burn Rate
B23: =B5 -> Washable Gowns | D23: ='Daily Data Entry'!D59 -> #VALUE! | E23: ='Daily Data Entry'!E59 -> #VALUE! | F23: ='Daily Data Entry'!F59 -> #VALUE! | G23: ='Daily Data Entry'!G59 -> #VALUE! | H23: ='Daily Data Entry'!H59 -> #VALUE! | I23: ='Daily Data Entry'!I59 -> #VALUE! | J23: ='Daily Data Entry'!J59 -> #VALUE! | K23: ='Daily Data Entry'!K59 -> #VALUE! | ... Q23: ='Daily Data Entry'!Q59 -> #VALUE! | S23: =B5 -> Washable Gowns | U23: ='Daily Data Entry'!V59
B24: Gloves (pairs) | C24: =IF(C6="","",C6) -> small | D24: ='Daily Data Entry'!D60 -> #VALUE! | E24: ='Daily Data Entry'!E60 -> #VALUE! | F24: ='Daily Data Entry'!F60 -> #VALUE! | G24: ='Daily Data Entry'!G60 -> #VALUE! | H24: ='Daily Data Entry'!H60 -> #VALUE! | I24: ='Daily Data Entry'!I60 -> #VALUE! | J24: ='Daily Data Entry'!J60 -> #VALUE! | K24: ='Daily Data Entry'!K60 -> #VALUE! | ... Q24: ='Daily Data Entry'!Q60 -> #VALUE! | S24: Gloves (pairs) | T24: =C6 -> small | U24: ='Daily Data Entry'!V60
C25: =IF(C7="","",C7) -> medium | D25: ='Daily Data Entry'!D61 -> #VALUE! | E25: ='Daily Data Entry'!E61 -> #VALUE! | F25: ='Daily Data Entry'!F61 -> #VALUE! | G25: ='Daily Data Entry'!G61 -> #VALUE! | H25: ='Daily Data Entry'!H61 -> #VALUE! | I25: ='Daily Data Entry'!I61 -> #VALUE! | J25: ='Daily Data Entry'!J61 -> #VALUE! | K25: ='Daily Data Entry'!K61 -> #VALUE! | ... Q25: ='Daily Data Entry'!Q61 -> #VALUE! | T25: =C7 -> medium | U25: ='Daily Data Entry'!V61
C26: =IF(C8="","",C8) -> large | D26: ='Daily Data Entry'!D62 -> #VALUE! | E26: ='Daily Data Entry'!E62 -> #VALUE! | F26: ='Daily Data Entry'!F62 -> #VALUE! | G26: ='Daily Data Entry'!G62 -> #VALUE! | H26: ='Daily Data Entry'!H62 -> #VALUE! | I26: ='Daily Data Entry'!I62 -> #VALUE! | J26: ='Daily Data Entry'!J62 -> #VALUE! | K26: ='Daily Data Entry'!K62 -> #VALUE! | ... Q26: ='Daily Data Entry'!Q62 -> #VALUE! | T26: =C8 -> large | U26: ='Daily Data Entry'!V62
C27: =IF(C9="","",C9) -> extra large | D27: ='Daily Data Entry'!D63 -> #VALUE! | E27: ='Daily Data Entry'!E63 -> #VALUE! | F27: ='Daily Data Entry'!F63 -> #VALUE! | G27: ='Daily Data Entry'!G63 -> #VALUE! | H27: ='Daily Data Entry'!H63 -> #VALUE! | I27: ='Daily Data Entry'!I63 -> #VALUE! | J27: ='Daily Data Entry'!J63 -> #VALUE! | K27: ='Daily Data Entry'!K63 -> #VALUE! | ... Q27: ='Daily Data Entry'!Q63 -> #VALUE! | T27: =C9 -> extra large | U27: ='Daily Data Entry'!V63
B28: =B10 -> N95 Masks | D28: ='Daily Data Entry'!D64 -> #VALUE! | E28: ='Daily Data Entry'!E64 -> #VALUE! | F28: ='Daily Data Entry'!F64 -> #VALUE! | G28: ='Daily Data Entry'!G64 -> #VALUE! | H28: ='Daily Data Entry'!H64 -> #VALUE! | I28: ='Daily Data Entry'!I64 -> #VALUE! | J28: ='Daily Data Entry'!J64 -> #VALUE! | K28: ='Daily Data Entry'!K64 -> #VALUE! | ... Q28: ='Daily Data Entry'!Q64 -> #VALUE! | S28: =B10 -> N95 Masks | U28: ='Daily Data Entry'!V64
B29: =B11 -> Surgical Masks | D29: ='Daily Data Entry'!D65 -> #VALUE! | E29: ='Daily Data Entry'!E65 -> #VALUE! | F29: ='Daily Data Entry'!F65 -> #VALUE! | G29: ='Daily Data Entry'!G65 -> #VALUE! | H29: ='Daily Data Entry'!H65 -> #VALUE! | I29: ='Daily Data Entry'!I65 -> #VALUE! | J29: ='Daily Data Entry'!J65 -> #VALUE! | K29: ='Daily Data Entry'!K65 -> #VALUE! | ... Q29: ='Daily Data Entry'!Q65 -> #VALUE! | S29: =B11 -> Surgical Masks | U29: ='Daily Data Entry'!V65
B30: =B12 -> Respirators | D30: ='Daily Data Entry'!D66 -> #VALUE! | E30: ='Daily Data Entry'!E66 -> #VALUE! | F30: ='Daily Data Entry'!F66 -> #VALUE! | G30: ='Daily Data Entry'!G66 -> #VALUE! | H30: ='Daily Data Entry'!H66 -> #VALUE! | I30: ='Daily Data Entry'!I66 -> #VALUE! | J30: ='Daily Data Entry'!J66 -> #VALUE! | K30: ='Daily Data Entry'!K66 -> #VALUE! | ... Q30: ='Daily Data Entry'!Q66 -> #VALUE! | S30: =B12 -> Respirators | U30: ='Daily Data Entry'!V66
B31: =B13 -> Face Shields | D31: ='Daily Data Entry'!D67 -> #VALUE! | E31: ='Daily Data Entry'!E67 -> #VALUE! | F31: ='Daily Data Entry'!F67 -> #VALUE! | G31: ='Daily Data Entry'!G67 -> #VALUE! | H31: ='Daily Data Entry'!H67 -> #VALUE! | I31: ='Daily Data Entry'!I67 -> #VALUE! | J31: ='Daily Data Entry'!J67 -> #VALUE! | K31: ='Daily Data Entry'!K67 -> #VALUE! | ... Q31: ='Daily Data Entry'!Q67 -> #VALUE! | S31: =B13 -> Face Shields | U31: ='Daily Data Entry'!V67
B32: =IF(B14="","",B14) -> Eye Protection - Goggles | D32: ='Daily Data Entry'!D68 -> #VALUE! | E32: ='Daily Data Entry'!E68 -> #VALUE! | F32: ='Daily Data Entry'!F68 -> #VALUE! | G32: ='Daily Data Entry'!G68 -> #VALUE! | H32: ='Daily Data Entry'!H68 -> #VALUE! | I32: ='Daily Data Entry'!I68 -> #VALUE! | J32: ='Daily Data Entry'!J68 -> #VALUE! | K32: ='Daily Data Entry'!K68 -> #VALUE! | ... Q32: ='Daily Data Entry'!Q68 -> #VALUE! | S32: =B14 -> Eye Protection - Goggles | U32: ='Daily Data Entry'!V68
B33: ='Daily Data Entry'!B50:C50 -> Disposable Gowns | D33: ='Daily Data Entry'!D69 -> #VALUE! | E33: ='Daily Data Entry'!E69 -> #VALUE! | F33: ='Daily Data Entry'!F69 -> #VALUE! | G33: ='Daily Data Entry'!G69 -> #VALUE! | H33: ='Daily Data Entry'!H69 -> #VALUE! | I33: ='Daily Data Entry'!I69 -> #VALUE! | J33: ='Daily Data Entry'!J69 -> #VALUE! | K33: ='Daily Data Entry'!K69 -> #VALUE! | ... Q33: ='Daily Data Entry'!Q69 -> #VALUE! | S33: =B15 -> Disposable Gowns | U33: ='Daily Data Entry'!V69
B34: ='Daily Data Entry'!B51:C51 -> Fluid Resistant Gowns | D34: ='Daily Data Entry'!D70 -> #VALUE! | E34: ='Daily Data Entry'!E70 -> #VALUE! | F34: ='Daily Data Entry'!F70 -> #VALUE! | G34: ='Daily Data Entry'!G70 -> #VALUE! | H34: ='Daily Data Entry'!H70 -> #VALUE! | I34: ='Daily Data Entry'!I70 -> #VALUE! | J34: ='Daily Data Entry'!J70 -> #VALUE! | K34: ='Daily Data Entry'!K70 -> #VALUE! | ... Q34: ='Daily Data Entry'!Q70 -> #VALUE! | S34: =B16 -> Fluid Resistant Gowns | U34: ='Daily Data Entry'!V70
B35: ='Daily Data Entry'!B52:C52 -> Other | D35: ='Daily Data Entry'!D71 -> #VALUE! | E35: ='Daily Data Entry'!E71 -> #VALUE! | F35: ='Daily Data Entry'!F71 -> #VALUE! | G35: ='Daily Data Entry'!G71 -> #VALUE! | H35: ='Daily Data Entry'!H71 -> #VALUE! | I35: ='Daily Data Entry'!I71 -> #VALUE! | J35: ='Daily Data Entry'!J71 -> #VALUE! | K35: ='Daily Data Entry'!K71 -> #VALUE! | ... Q35: ='Daily Data Entry'!Q71 -> #VALUE! | S35: =B17 -> Other | U35: ='Daily Data Entry'!V71
B36: ='Daily Data Entry'!B53:C53 -> Other | D36: ='Daily Data Entry'!D72 -> #VALUE! | E36: ='Daily Data Entry'!E72 -> #VALUE! | F36: ='Daily Data Entry'!F72 -> #VALUE! | G36: ='Daily Data Entry'!G72 -> #VALUE! | H36: ='Daily Data Entry'!H72 -> #VALUE! | I36: ='Daily Data Entry'!I72 -> #VALUE! | J36: ='Daily Data Entry'!J72 -> #VALUE! | K36: ='Daily Data Entry'!K72 -> #VALUE! | ... Q36: ='Daily Data Entry'!Q72 -> #VALUE! | S36: =B18 -> Other | U36: ='Daily Data Entry'!V72
B37: ='Daily Data Entry'!B54:C54 -> Other | D37: ='Daily Data Entry'!D73 -> #VALUE! | E37: ='Daily Data Entry'!E73 -> #VALUE! | F37: ='Daily Data Entry'!F73 -> #VALUE! | G37: ='Daily Data Entry'!G73 -> #VALUE! | H37: ='Daily Data Entry'!H73 -> #VALUE! | I37: ='Daily Data Entry'!I73 -> #VALUE! | J37: ='Daily Data Entry'!J73 -> #VALUE! | K37: ='Daily Data Entry'!K73 -> #VALUE! | ... Q37: ='Daily Data Entry'!Q73 -> #VALUE! | S37: =B19 -> Other | U37: ='Daily Data Entry'!V73
B39: Amount of PPE used per patient (negative numbers indicate daily supply increase)
B40: Type of PPE | D40: Day 1 -Day 2 | E40: Day 2 - Day 3 | F40: Day 3 - Day 4 | G40: Day 4 - Day 5 | H40: Day 5 - Day 6 | I40: Day 6 - Day 7 | J40: Day 7 - Day 8 | K40: Day 8 - Day 9 | L40: Day 9 - Day 10 | M40: Day 10 - Day 11 | N40: Day 11 - Day 12 | O40: Day 12 - Day 13 | P40: Day 13 - Day 14
B41: =B23 -> Washable Gowns | D41: ='Daily Data Entry'!D78 | E41: ='Daily Data Entry'!E78 | F41: ='Daily Data Entry'!F78 | G41: ='Daily Data Entry'!G78 | H41: ='Daily Data Entry'!H78 | I41: ='Daily Data Entry'!I78 | J41: ='Daily Data Entry'!J78 | K41: ='Daily Data Entry'!K78 | ... P41: ='Daily Data Entry'!P78
B42: Gloves (pairs) | C42: =IF(C24="","",C24) -> small | D42: ='Daily Data Entry'!D79 | E42: ='Daily Data Entry'!E79 | F42: ='Daily Data Entry'!F79 | G42: ='Daily Data Entry'!G79 | H42: ='Daily Data Entry'!H79 | I42: ='Daily Data Entry'!I79 | J42: ='Daily Data Entry'!J79 | K42: ='Daily Data Entry'!K79 | ... P42: ='Daily Data Entry'!P79
C43: =IF(C25="","",C25) -> medium | D43: ='Daily Data Entry'!D80 | E43: ='Daily Data Entry'!E80 | F43: ='Daily Data Entry'!F80 | G43: ='Daily Data Entry'!G80 | H43: ='Daily Data Entry'!H80 | I43: ='Daily Data Entry'!I80 | J43: ='Daily Data Entry'!J80 | K43: ='Daily Data Entry'!K80 | ... P43: ='Daily Data Entry'!P80
C44: =IF(C26="","",C26) -> large | D44: ='Daily Data Entry'!D81 | E44: ='Daily Data Entry'!E81 | F44: ='Daily Data Entry'!F81 | G44: ='Daily Data Entry'!G81 | H44: ='Daily Data Entry'!H81 | I44: ='Daily Data Entry'!I81 | J44: ='Daily Data Entry'!J81 | K44: ='Daily Data Entry'!K81 | ... P44: ='Daily Data Entry'!P81
...
